Workbook

Sheet SOUTH Wells
A1: DETAIL OF EXPENDITURE APPROVAL for SOUTH Wells
A2: CONTRACT NO. | C2: OGDCL-SCM-SERVICES-CB-CEM-278762293-4600000959-2025
A3: COMPANY NAME | C3: M/s Sprint Oil & Gas Services FZ-Pakistan
A4: Expenditure Approved | B4: Contract Amount | C4: 4704544
J5: Approved Amount | L5: Use Amount | M5: Usage %
E7: Total Approved | J7: =K5+K6+C4+C5+C6+G5+G6 -> 4704544 | L7: =SUM(K9:K282) -> 2141036.8 | M7: =L7/J7*100 -> 45.509976
A8: SNO | B8: INVOICE NO. | C8: DATE. | D8: Rig | E8: NAME OF WELL | F8: Description | G8: Claimed Amount Exl Tax (USD) | H8: GST/PST | I8: Tax | J8: AMOUNT Inclusive tax (USD) | K8: Amount Paid | L8: COMMULATIVE EXPENDITURE (USD) | M8: Status | N8: Quarter | O8: Year | P8: Release order no. | Q8: Service Entry Sheet no. | R8: Contract Value Consumed | S8: Clearance date
A9: 1 | B9: 994859574 | C9: 45678 | E9: GURGALOT X-1 | F9: Mob of cementing package (Returned to vendor as 16 % PST applied intead of 15% old invice num is 994859501) | G9: 68300 | I9: =G9*H9/100 -> 0 | J9: =G9+I9 -> 68300 | K9: =J9 -> 68300 | L9: =K9 -> 68300 | M9: Cleared | N9: =IF(S9="","",CHOOSE(INT(MOD(MONTH(S9)-7,12)/3)+1,"Q1","Q2","Q3","Q4")) | O9: =IF(S9="","",YEAR(S9)) | P9: 4700017534 | Q9: 1000063669 | R9: =L9/4707544 -> 0.014508627
A10: 2 | B10: 994859502 | C10: 45682 | E10: BARAGZAI X-1 | F10: Mob of additional Eqp | G10: 39220 | I10: =G10*H10/100 -> 0 | J10: =G10+I10 -> 39220 | K10: =J10 -> 39220 | L10: =L9+K10 -> 107520 | M10: Cleared | N10: =IF(S10="","",CHOOSE(INT(MOD(MONTH(S10)-7,12)/3)+1,"Q1","Q2","Q3","Q4")) | O10: =IF(S10="","",YEAR(S10)) | P10: 4700017529 | Q10: 1000063662 | R10: =L10/4707544 -> 0.022839935
A11: 3 | B11: 994859510 | C11: 45687 | E11: BARAGZAI X-1 | F11: 11 3/4" liner job | G11: 65629 | I11: =G11*H11/100 -> 0 | J11: =G11+I11 -> 65629 | K11: =J11 -> 65629 | L11: =L10+K11 -> 173149 | M11: Cleared | N11: =IF(S11="","",CHOOSE(INT(MOD(MONTH(S11)-7,12)/3)+1,"Q1","Q2","Q3","Q4")) | O11: =IF(S11="","",YEAR(S11)) | P11: 4700017572 | Q11: 1000063844 | R11: =L11/4707544 -> 0.036781175
A12: 4 | B12: 994859557 | C12: 45698 | E12: BARAGZAI X-1 | F12: Additional Eqp(unit & Batch mixer) Charges | G12: 3500 | I12: =G12*H12/100 -> 0 | J12: =G12+I12 -> 3500 | K12: =J12 -> 3500 | L12: =L11+K12 -> 176649 | M12: Cleared | N12: =IF(S12="","",CHOOSE(INT(MOD(MONTH(S12)-7,12)/3)+1,"Q1","Q2","Q3","Q4")) | O12: =IF(S12="","",YEAR(S12)) | P12: 4700017621 | Q12: 1000063997 | R12: =L12/4707544 -> 0.037524663
A13: 5 | B13: 994859735 | C13: 45704 | E13: GURGALOT X-1 | F13: (Returned to vendor as 16 % PST applied intead of 15%old invice num is 994859558) | G13: 7600 | I13: =G13*H13/100 -> 0 | J13: =G13+I13 -> 7600 | K13: =J13 -> 7600 | L13: =L12+K13 -> 184249 | M13: Cleared | N13: =IF(S13="","",CHOOSE(INT(MOD(MONTH(S13)-7,12)/3)+1,"Q1","Q2","Q3","Q4")) | O13: =IF(S13="","",YEAR(S13)) | P13: 4700017579 | Q13: 1000063858 | R13: =L13/4707544 -> 0.039139092
A14: 6 | B14: 994859544 | C14: 45695 | E14: Toot Deep-1 | F14: Squeez Plug (08.07.2025) | G14: 4350 | I14: =G14*H14/100 -> 0 | J14: =G14+I14 -> 4350 | K14: =J14 -> 4350 | L14: =L13+K14 -> 188599 | M14: Cleared | N14: =IF(S14="","",CHOOSE(INT(MOD(MONTH(S14)-7,12)/3)+1,"Q1","Q2","Q3","Q4")) | O14: =IF(S14="","",YEAR(S14)) | P14: 4700017916 | Q14: 1000065650 | R14: =L14/4707544 -> 0.040063141
A15: 7 | B15: 994859637 | C15: 45708 | E15: BARAGZAI X-1 | F15: 9 5/8" job (19.08.2025) | G15: 166050 | I15: =G15*H15/100 -> 0 | J15: =G15+I15 -> 166050 | K15: =J15 -> 166050 | L15: =L14+K15 -> 354649 | M15: Cleared | N15: =IF(S15="","",CHOOSE(INT(MOD(MONTH(S15)-7,12)/3)+1,"Q1","Q2","Q3","Q4")) | O15: =IF(S15="","",YEAR(S15)) | P15: 4700017939 | Q15: 1000066037 | R15: =L15/4707544 -> 0.075336311
A16: 8 | B16: 994859648 | C16: 45730 | E16: GURGALOT X-1 | F16: Additives for 24 1/2" Job | G16: 8480 | I16: =G16*H16/100 -> 0 | J16: =G16+I16 -> 8480 | K16: =J16 -> 8480 | L16: =L15+K16 -> 363129 | M16: Cleared | N16: =IF(S16="","",CHOOSE(INT(MOD(MONTH(S16)-7,12)/3)+1,"Q1","Q2","Q3","Q4")) | O16: =IF(S16="","",YEAR(S16)) | P16: 4700017938 | Q16: 1000066041 | R16: =L16/4707544 -> 0.077137675
A17: 9 | B17: 994859676 | C17: 45733 | E17: Toot Deep-1 | F17: Squeez Plug 1 (04.09.2025) | G17: 4350 | I17: =G17*H17/100 -> 0 | J17: =G17+I17 -> 4350 | K17: =J17 -> 4350 | L17: =L16+K17 -> 367479 | M17: Cleared | N17: =IF(S17="","",CHOOSE(INT(MOD(MONTH(S17)-7,12)/3)+1,"Q1","Q2","Q3","Q4")) | O17: =IF(S17="","",YEAR(S17)) | P17: 4700018445 | Q17: 1000067588 | R17: =L17/4707544 -> 0.078061724
A18: 10 | B18: 994859701 | C18: 45733 | E18: Toot Deep-1 | F18: Squeez Plug 2 (08.09.2025) | G18: 4350 | I18: =G18*H18/100 -> 0 | J18: =G18+I18 -> 4350 | K18: =J18 -> 4350 | L18: =L17+K18 -> 371829 | M18: Cleared | N18: =IF(S18="","",CHOOSE(INT(MOD(MONTH(S18)-7,12)/3)+1,"Q1","Q2","Q3","Q4")) | O18: =IF(S18="","",YEAR(S18)) | P18: 4700018803 | Q18: 1000069144 | R18: =L18/4707544 -> 0.078985773
A19: 11 | B19: 994859699 | C19: 45737 | E19: Toot Deep-1 | F19: Squeez Plug 3 (14.09.2025) | G19: 4350 | I19: =G19*H19/100 -> 0 | J19: =G19+I19 -> 4350 | K19: =J19 -> 4350 | L19: =L18+K19 -> 376179 | M19: Cleared | N19: =IF(S19="","",CHOOSE(INT(MOD(MONTH(S19)-7,12)/3)+1,"Q1","Q2","Q3","Q4")) | O19: =IF(S19="","",YEAR(S19)) | P19: 4700018814 | Q19: 1000069152 | R19: =L19/4707544 -> 0.079909821
A20: 12 | B20: 994859700 | C20: 17-31 Jan-25 | E20: Toot Deep-1 | F20: Squeez Plug 4 (20.09.2025) | G20: 4350 | I20: =G20*H20/100 -> 0 | J20: =G20+I20 -> 4350 | K20: =J20 -> 4350 | L20: =L19+K20 -> 380529 | M20: Cleared | N20: =IF(S20="","",CHOOSE(INT(MOD(MONTH(S20)-7,12)/3)+1,"Q1","Q2","Q3","Q4")) | O20: =IF(S20="","",YEAR(S20)) | P20: 4700018815 | Q20: 1000069155 | R20: =L20/4707544 -> 0.08083387
A21: 13 | B21: 994859698 | C21: 17-31 Jan-25 | E21: GURGALOT X-1 | F21: Additional Eqp(Frac Tank) Charges | G21: 7600 | I21: =G21*H21/100 -> 0 | J21: =G21+I21 -> 7600 | K21: =J21 -> 7600 | L21: =L20+K21 -> 388129 | M21: Cleared | N21: =IF(S21="","",CHOOSE(INT(MOD(MONTH(S21)-7,12)/3)+1,"Q1","Q2","Q3","Q4")) | O21: =IF(S21="","",YEAR(S21)) | P21: 4700018915 | Q21: 1000069622 | R21: =L21/4707544 -> 0.0824483
A22: 14 | B22: 994859702 | C22: 01-28 Feb-25 | E22: GURGALOT X-1 | F22: 18 5/8" Casing | G22: 80730 | I22: =G22*H22/100 -> 0 | J22: =G22+I22 -> 80730 | K22: =J22 -> 80730 | L22: =L21+K22 -> 468859 | M22: Cleared | N22: =IF(S22="","",CHOOSE(INT(MOD(MONTH(S22)-7,12)/3)+1,"Q1","Q2","Q3","Q4")) | O22: =IF(S22="","",YEAR(S22)) | P22: 4700019048 | Q22: 1000070334 | R22: =L22/4707544 -> 0.09959737
A23: 15 | B23: 994859638 | C23: 45749 | E23: BETTANI DEEP-1 | F23: 5" LINER JOB | G23: 17475 | I23: =G23*H23/100 -> 0 | J23: =G23+I23 -> 17475 | K23: =J23 -> 17475 | L23: =L22+K23 -> 486334 | M23: Cleared | N23: =IF(S23="","",CHOOSE(INT(MOD(MONTH(S23)-7,12)/3)+1,"Q1","Q2","Q3","Q4")) | O23: =IF(S23="","",YEAR(S23)) | P23: 4700019304 | Q23: 1000071154 | R23: =L23/4707544 -> 0.1033095
A24: 16 | B24: 994859672 | C24: 45754 | E24: BETTANI DEEP-1 | F24: 7" Tie back liner | G24: 11475 | I24: =G24*H24/100 -> 0 | J24: =G24+I24 -> 11475 | K24: =J24 -> 11475 | L24: =L23+K24 -> 497809 | M24: Cleared | N24: =IF(S24="","",CHOOSE(INT(MOD(MONTH(S24)-7,12)/3)+1,"Q1","Q2","Q3","Q4")) | O24: =IF(S24="","",YEAR(S24)) | P24: 4700019264 | Q24: 1000071018 | R24: =L24/4707544 -> 0.10574707
A25: 17 | B25: 994859785 | C25: 1-30 Mar-25 | E25: BETTANI DEEP-1 | F25: De Mob of Cementing Pacakge | G25: 119525 | I25: =G25*H25/100 -> 0 | J25: =G25+I25 -> 119525 | K25: =J25 -> 119525 | L25: =L24+K25 -> 617334 | M25: Cleared | N25: =IF(S25="","",CHOOSE(INT(MOD(MONTH(S25)-7,12)/3)+1,"Q1","Q2","Q3","Q4")) | O25: =IF(S25="","",YEAR(S25)) | P25: 4700019310 | Q25: 1000071182 | R25: =L25/4707544 -> 0.13113717
A26: 18 | B26: 994859647 | C26: 1-28 Feb-25 | E26: BARAGZAI X-1 | F26: Additional Eqp DeMob | G26: 21010 | I26: =G26*H26/100 -> 0 | J26: =G26+I26 -> 21010 | K26: =J26 -> 21010 | L26: =L25+K26 -> 638344 | M26: Cleared | N26: =IF(S26="","",CHOOSE(INT(MOD(MONTH(S26)-7,12)/3)+1,"Q1","Q2","Q3","Q4")) | O26: =IF(S26="","",YEAR(S26)) | P26: 4700018563 | Q26: 1000068333 | R26: =L26/4707544 -> 0.13560022
A27: 19 | B27: 994859843 | C27: 45774 | E27: BARAGZAI X-1 | F27: 5" LINER JOB | G27: 11640 | I27: =G27*H27/100 -> 0 | J27: =G27+I27 -> 11640 | K27: =J27 -> 11640 | L27: =L26+K27 -> 649984 | M27: Cleared | N27: =IF(S27="","",CHOOSE(INT(MOD(MONTH(S27)-7,12)/3)+1,"Q1","Q2","Q3","Q4")) | O27: =IF(S27="","",YEAR(S27)) | P27: 4700019494 | Q27: 1000072260 | R27: =L27/4707544 -> 0.13807285
A28: 20 | B28: 994859847 | C28: 1-16 Mar-25 | E28: RAJIAN-09 | F28: Isolation/Squeee plug | G28: 4110 | I28: =G28*H28/100 -> 0 | J28: =G28+I28 -> 4110 | K28: =J28 -> 4110 | L28: =L27+K28 -> 654094 | M28: Cleared | N28: =IF(S28="","",CHOOSE(INT(MOD(MONTH(S28)-7,12)/3)+1,"Q1","Q2","Q3","Q4")) | O28: =IF(S28="","",YEAR(S28)) | P28: 4700019516 | Q28: 1000072316 | R28: =L28/4707544 -> 0.13894591
A29: 21 | B29: 994859871 | C29: 45757 | E29: GURGALOT X-1 | F29: Mob/Demob of add silos | G29: 38000 | I29: =G29*H29/100 -> 0 | J29: =G29+I29 -> 38000 | K29: =J29 -> 38000 | L29: =L28+K29 -> 692094 | M29: Cleared | N29: =IF(S29="","",CHOOSE(INT(MOD(MONTH(S29)-7,12)/3)+1,"Q1","Q2","Q3","Q4")) | O29: =IF(S29="","",YEAR(S29)) | P29: 4700019564 | Q29: 1000072468 | R29: =L29/4707544 -> 0.14701806
A30: 22 | B30: 994859842 | C30: 45786 | E30: BARAGZAI X-1 | F30: 7" Liner Job (29.09.2025) | G30: 34720 | I30: =G30*H30/100 -> 0 | J30: =G30+I30 -> 34720 | K30: =J30 -> 34720 | L30: =L29+K30 -> 726814 | M30: Cleared | N30: =IF(S30="","",CHOOSE(INT(MOD(MONTH(S30)-7,12)/3)+1,"Q1","Q2","Q3","Q4")) | O30: =IF(S30="","",YEAR(S30)) | P30: 4700019504 | Q30: 1000072280 | R30: =L30/4707544 -> 0.15439346
A31: 23 | B31: 994859863 | C31: 17-31 Jan-25 | E31: RAJIAN-02 | F31: Mob of Cmt Pkg | G31: 683 | I31: =G31*H31/100 -> 0 | J31: =G31+I31 -> 683 | K31: =J31 -> 683 | L31: =L30+K31 -> 727497 | M31: Cleared | N31: =IF(S31="","",CHOOSE(INT(MOD(MONTH(S31)-7,12)/3)+1,"Q1","Q2","Q3","Q4")) | O31: =IF(S31="","",YEAR(S31)) | P31: 4700019669 | Q31: 1000073134 | R31: =L31/4707544 -> 0.15453854
A32: 24 | B32: 994859872 | C32: 1-31 Mar-25 | E32: RAJIAN-09 | F32: Mob of Cmt Pkg | G32: 37565 | I32: =G32*H32/100 -> 0 | J32: =G32+I32 -> 37565 | K32: =J32 -> 37565 | L32: =L31+K32 -> 765062 | M32: Cleared | N32: =IF(S32="","",CHOOSE(INT(MOD(MONTH(S32)-7,12)/3)+1,"Q1","Q2","Q3","Q4")) | O32: =IF(S32="","",YEAR(S32)) | P32: 47000019677 | Q32: 1000073154 | R32: =L32/4707544 -> 0.16251829
A33: 25 | B33: 994859893 | C33: 45804 | E33: RAJIAN-02 | F33: Isolation/Squeee plug | G33: 4250 | I33: =G33*H33/100 -> 0 | J33: =G33+I33 -> 4250 | K33: =J33 -> 4250 | L33: =L32+K33 -> 769312 | M33: Cleared | N33: =IF(S33="","",CHOOSE(INT(MOD(MONTH(S33)-7,12)/3)+1,"Q1","Q2","Q3","Q4")) | O33: =IF(S33="","",YEAR(S33)) | P33: 4700019885 | Q33: 1000073942 | R33: =L33/4707544 -> 0.1634211
A34: 26 | B34: 994859894 | C34: 1-28 Feb-25 | E34: RAJIAN-02 | F34: Isolation/Squeee plug 2 | G34: 4850 | I34: =G34*H34/100 -> 0 | J34: =G34+I34 -> 4850 | K34: =J34 -> 4850 | L34: =L33+K34 -> 774162 | M34: Cleared | N34: =IF(S34="","",CHOOSE(INT(MOD(MONTH(S34)-7,12)/3)+1,"Q1","Q2","Q3","Q4")) | O34: =IF(S34="","",YEAR(S34)) | P34: 4700019886 | Q34: 1000073944 | R34: =L34/4707544 -> 0.16445136
A35: 27 | B35: 994859921 | C35: 45825 | E35: RAJIAN-02 | F35: Isolation/Squeee plug 3 | G35: 4490 | I35: =G35*H35/100 -> 0 | J35: =G35+I35 -> 4490 | K35: =J35 -> 4490 | L35: =L34+K35 -> 778652 | M35: Cleared | N35: =IF(S35="","",CHOOSE(INT(MOD(MONTH(S35)-7,12)/3)+1,"Q1","Q2","Q3","Q4")) | O35: =IF(S35="","",YEAR(S35)) | P35: 4700019887 | Q35: 1000073951 | R35: =L35/4707544 -> 0.16540515
A36: 28 | B36: 994859954 | C36: 45824 | E36: GURGALOT X-1 | F36: 13 3/8" Casing | G36: 287550 | I36: =G36*H36/100 -> 0 | J36: =G36+I36 -> 287550 | K36: =J36 -> 287550 | L36: =L35+K36 -> 1066202 | M36: Cleared | N36: =IF(S36="","",CHOOSE(INT(MOD(MONTH(S36)-7,12)/3)+1,"Q1","Q2","Q3","Q4")) | O36: =IF(S36="","",YEAR(S36)) | P36: 4700020173 | Q36: 1000075059 | R36: =L36/4707544 -> 0.22648795
A37: 29 | B37: 994860010 | C37: 1-31 May-25 | E37: KAL-03 | F37: Isolation plug | G37: 3400 | I37: =G37*H37/100 -> 0 | J37: =G37+I37 -> 3400 | K37: =J37 -> 3400 | L37: =L36+K37 -> 1069602 | M37: Cleared | N37: =IF(S37="","",CHOOSE(INT(MOD(MONTH(S37)-7,12)/3)+1,"Q1","Q2","Q3","Q4")) | O37: =IF(S37="","",YEAR(S37)) | P37: 4700021276 | Q37: 1000079748 | R37: =L37/4707544 -> 0.2272102
A38: 30 | B38: 994860011 | C38: 1-30 April-25 | E38: GURGALOT X-1 | F38: Demob of additional eqp | G38: 26220 | I38: =G38*H38/100 -> 0 | J38: =G38+I38 -> 26220 | K38: =J38 -> 26220 | L38: =L37+K38 -> 1095822 | M38: Cleared | N38: =IF(S38="","",CHOOSE(INT(MOD(MONTH(S38)-7,12)/3)+1,"Q1","Q2","Q3","Q4")) | O38: =IF(S38="","",YEAR(S38)) | P38: 4700021279 | Q38: 1000079767 | R38: =L38/4707544 -> 0.23277998
A39: 31 | B39: 994860039 | C39: 1-31 May-25 | E39: RAJIAN-02 | F39: P & A (Surface) | G39: 5940 | I39: =G39*H39/100 -> 0 | J39: =G39+I39 -> 5940 | K39: =J39 -> 5940 | L39: =L38+K39 -> 1101762 | M39: Cleared | N39: =IF(S39="","",CHOOSE(INT(MOD(MONTH(S39)-7,12)/3)+1,"Q1","Q2","Q3","Q4")) | O39: =IF(S39="","",YEAR(S39)) | P39: 4700021367 | Q39: 1000080097 | R39: =L39/4707544 -> 0.23404178
A40: 32 | B40: 994860040 | C40: 23-30 June-25 | E40: RAJIAN-02 | F40: P & A (Bottom) | G40: 10150 | I40: =G40*H40/100 -> 0 | J40: =G40+I40 -> 10150 | K40: =J40 -> 10150 | L40: =L39+K40 -> 1111912 | M40: Cleared | N40: =IF(S40="","",CHOOSE(INT(MOD(MONTH(S40)-7,12)/3)+1,"Q1","Q2","Q3","Q4")) | O40: =IF(S40="","",YEAR(S40)) | P40: 4700021859 | Q40: 1000081815 | R40: =L40/4707544 -> 0.2361979
A41: 33 | B41: 994860195 | C41: 29-30 June-25 | E41: BARAGZAI X-1 | F41: Demob of Cementing Package | G41: 80252.5 | I41: =G41*H41/100 -> 0 | J41: =G41+I41 -> 80252.5 | K41: =J41 -> 80252.5 | L41: =L40+K41 -> 1192164.5 | M41: Cleared | N41: =IF(S41="","",CHOOSE(INT(MOD(MONTH(S41)-7,12)/3)+1,"Q1","Q2","Q3","Q4")) | O41: =IF(S41="","",YEAR(S41)) | P41: 4700022146 | Q41: 1000082905 | R41: =L41/4707544 -> 0.25324554
...

Sheet Covering Letter South 
A1: =L2 -> 18 | B1: Ref. para 15 /N. | J1: S.No of South well | L1: INSERT 1ST PARAGRAPH NO
A2: =A1+1 -> 19 | B2: The invoice No. | C2: =K4 -> 994859574 | J2: 1 | L2: 18
B3: has been verified in the light of terms, conditions and price list of the
B4: contract No.OGDCL-SCM-SERVICES-CB-CEM-265732025-4600000803-2025 | J4: Invoice No | K4: =_xlfn.XLOOKUP($J$2,'SOUTH Wells'!$A:$A,'SOUTH Wells'!$B:$B,"") -> 994859574
B5: with M/s Sprint Oil & Gas Services for providing their services at well | G5: =K5 -> GURGALOT X-1 | J5: Well Name | K5: =_xlfn.XLOOKUP($J$2,'SOUTH Wells'!$A:$A,'SOUTH Wells'!$E:$E,"") -> GURGALOT X-1
A7: =A2+1 -> 20 | B7: The claimed invoicing amount is US $ | D7: =J7 -> 68300 | E7: {=DollarAmount(D7)} -> Sixty-Eight Thousand Three Hundred Dollars and 00 Cents Only | J7: =IFERROR(INDEX('SOUTH Wells'!$G:$G,MATCH($J$2,'SOUTH Wells'!$A:$A,0)),"") -> 68300 | K7: Claimed amount
A8: =A7+1 -> 21 | B8: The verified amount is | D8: =J8 -> 68300 | E8: {=DollarAmount(D8)} -> Sixty-Eight Thousand Three Hundred Dollars and 00 Cents Only | J8: =IFERROR(INDEX('SOUTH Wells'!$K:$K,MATCH($J$2,'SOUTH Wells'!$A:$A,0)),"") -> 68300 | K8: paid amount
B10: Copy of Service Entry Sheet is placed opposite. | J10: 1
J11: 2 & 3
J12: 4
A13: =A8+1 -> 22 | B13: Submitted for endorsement through AGM(DS) and onward dispatch to DCA (Services) for payment Please. | K13: {=SpellDollars(J8)} -> #NAME? | W13: =63*280 -> 17640
K14: =IF(J8=0,"Zero Dollars and Zero Cents",IF(INT(J8)=0,"",IF(INT(J8)<10000,TEXT(INT(J8),"[$-409]###0")&" Dollars","")))&IF(AND(INT(J8)>0,MOD(J8,1)<>0)," and ","")&IF(MOD(J8,1)=0,IF(INT(J8)=0,"","Zero Cents"),TRIM(TEXT(MOD(J8,1)*100,"[$-409]##0")&" Cents")) -> Zero Cents
I16: (Summer Nouman)
I17: Sr. Engr. (Cement)
I18: Ext:2572
A21: =A13+1 -> 23 | B21: Chief Engr. (Cmt Ops.)
A25: =A21+1 -> 24 | B25: AM (Cmt/Stim)
A28: =A25+1 -> 25 | B28: AGM (DS)
A31: =A28+1 -> 26 | B31: Dy.Chief Accountant (Services)

Sheet Print 
A1: DETAIL OF EXPENDITURE APPROVAL for SOUTH Wells
A2: CONTRACT NO. | C2: PROC-FD/CB/WS- 298-767379 /2012
A3: COMPANY NAME | C3: M/S SPRINT OIL & GAS SERVICES FZC
A4: Expenditure Approved | B4: Contract Amount | D4: balance amount | F4: %age Usage
B5: ='SOUTH Wells'!C4 -> 4704544 | D5: ='SOUTH Wells'!L7 -> 2141036.8 | F5: ='SOUTH Wells'!M7 -> 45.509976
A6: SNO | B6: INVOICE NO. | C6: DATE. | D6: NAME OF WELL | E6: AMOUNT VERIFIED (USD) | F6: BALANCE AMOUNT (USD) | G6: COMMULATIVE EXPENDITURE (USD)
A7: 1 | B7: =IF(A7>0,'SOUTH Wells'!B9,"") -> 994859574 | C7: =IF(A7>0,'SOUTH Wells'!C9,"") -> 45678 | D7: =IF(A7>0,'SOUTH Wells'!E9,"") -> GURGALOT X-1 | E7: =IF(A7>0,'SOUTH Wells'!K9,"") -> 68300 | F7: =IF(A7>0,$B$5-E7,"") -> 4636244 | G7: =E7 -> 68300
A8: 2 | B8: =IF(A8>0,'SOUTH Wells'!B10,"") -> 994859502 | C8: =IF(A8>0,'SOUTH Wells'!C10,"") -> 45682 | D8: =IF(A8>0,'SOUTH Wells'!E10,"") -> BARAGZAI X-1 | E8: =IF(A8>0,'SOUTH Wells'!K10,"") -> 39220 | F8: =IF(A8>0,F7-E8,"") -> 4597024 | G8: =IF(A8>0,G7+E8,"") -> 107520
A9: 3 | B9: =IF(A9>0,'SOUTH Wells'!B11,"") -> 994859510 | C9: =IF(A9>0,'SOUTH Wells'!C11,"") -> 45687 | D9: =IF(A9>0,'SOUTH Wells'!E11,"") -> BARAGZAI X-1 | E9: =IF(A9>0,'SOUTH Wells'!K11,"") -> 65629 | F9: =IF(A9>0,F8-E9,"") -> 4531395 | G9: =IF(A9>0,G8+E9,"") -> 173149
A10: 4 | B10: =IF(A10>0,'SOUTH Wells'!B12,"") -> 994859557 | C10: =IF(A10>0,'SOUTH Wells'!C12,"") -> 45698 | D10: =IF(A10>0,'SOUTH Wells'!E12,"") -> BARAGZAI X-1 | E10: =IF(A10>0,'SOUTH Wells'!K12,"") -> 3500 | F10: =IF(A10>0,F9-E10,"") -> 4527895 | G10: =IF(A10>0,G9+E10,"") -> 176649
A11: 5 | B11: =IF(A11>0,'SOUTH Wells'!B13,"") -> 994859735 | C11: =IF(A11>0,'SOUTH Wells'!C13,"") -> 45704 | D11: =IF(A11>0,'SOUTH Wells'!E13,"") -> GURGALOT X-1 | E11: =IF(A11>0,'SOUTH Wells'!K13,"") -> 7600 | F11: =IF(A11>0,F10-E11,"") -> 4520295 | G11: =IF(A11>0,G10+E11,"") -> 184249
A12: 6 | B12: =IF(A12>0,'SOUTH Wells'!B14,"") -> 994859544 | C12: =IF(A12>0,'SOUTH Wells'!C14,"") -> 45695 | D12: =IF(A12>0,'SOUTH Wells'!E14,"") -> Toot Deep-1 | E12: =IF(A12>0,'SOUTH Wells'!K14,"") -> 4350 | F12: =IF(A12>0,F11-E12,"") -> 4515945 | G12: =IF(A12>0,G11+E12,"") -> 188599
A13: 7 | B13: =IF(A13>0,'SOUTH Wells'!B15,"") -> 994859637 | C13: =IF(A13>0,'SOUTH Wells'!C15,"") -> 45708 | D13: =IF(A13>0,'SOUTH Wells'!E15,"") -> BARAGZAI X-1 | E13: =IF(A13>0,'SOUTH Wells'!K15,"") -> 166050 | F13: =IF(A13>0,F12-E13,"") -> 4349895 | G13: =IF(A13>0,G12+E13,"") -> 354649
A14: 8 | B14: =IF(A14>0,'SOUTH Wells'!B16,"") -> 994859648 | C14: =IF(A14>0,'SOUTH Wells'!C16,"") -> 45730 | D14: =IF(A14>0,'SOUTH Wells'!E16,"") -> GURGALOT X-1 | E14: =IF(A14>0,'SOUTH Wells'!K16,"") -> 8480 | F14: =IF(A14>0,F13-E14,"") -> 4341415 | G14: =IF(A14>0,G13+E14,"") -> 363129
A15: 9 | B15: =IF(A15>0,'SOUTH Wells'!B17,"") -> 994859676 | C15: =IF(A15>0,'SOUTH Wells'!C17,"") -> 45733 | D15: =IF(A15>0,'SOUTH Wells'!E17,"") -> Toot Deep-1 | E15: =IF(A15>0,'SOUTH Wells'!K17,"") -> 4350 | F15: =IF(A15>0,F14-E15,"") -> 4337065 | G15: =IF(A15>0,G14+E15,"") -> 367479
A16: 10 | B16: =IF(A16>0,'SOUTH Wells'!B18,"") -> 994859701 | C16: =IF(A16>0,'SOUTH Wells'!C18,"") -> 45733 | D16: =IF(A16>0,'SOUTH Wells'!E18,"") -> Toot Deep-1 | E16: =IF(A16>0,'SOUTH Wells'!K18,"") -> 4350 | F16: =IF(A16>0,F15-E16,"") -> 4332715 | G16: =IF(A16>0,G15+E16,"") -> 371829
A17: 11 | B17: =IF(A17>0,'SOUTH Wells'!B19,"") -> 994859699 | C17: =IF(A17>0,'SOUTH Wells'!C19,"") -> 45737 | D17: =IF(A17>0,'SOUTH Wells'!E19,"") -> Toot Deep-1 | E17: =IF(A17>0,'SOUTH Wells'!K19,"") -> 4350 | F17: =IF(A17>0,F16-E17,"") -> 4328365 | G17: =IF(A16>0,G16+E17,"") -> 376179
A18: 12 | B18: =IF(A18>0,'SOUTH Wells'!B20,"") -> 994859700 | C18: =IF(A18>0,'SOUTH Wells'!C20,"") -> 17-31 Jan-25 | D18: =IF(A18>0,'SOUTH Wells'!E20,"") -> Toot Deep-1 | E18: =IF(A18>0,'SOUTH Wells'!K20,"") -> 4350 | F18: =IF(A18>0,F17-E18,"") -> 4324015 | G18: =IF(A17>0,G17+E18,"") -> 380529
A19: 13 | B19: =IF(A19>0,'SOUTH Wells'!B21,"") -> 994859698 | C19: =IF(A19>0,'SOUTH Wells'!C21,"") -> 17-31 Jan-25 | D19: =IF(A19>0,'SOUTH Wells'!E21,"") -> GURGALOT X-1 | E19: =IF(A19>0,'SOUTH Wells'!K21,"") -> 7600 | F19: =IF(A19>0,F18-E19,"") -> 4316415 | G19: =IF(A18>0,G18+E19,"") -> 388129
A20: 14 | B20: =IF(A20>0,'SOUTH Wells'!B22,"") -> 994859702 | C20: =IF(A20>0,'SOUTH Wells'!C22,"") -> 01-28 Feb-25 | D20: =IF(A20>0,'SOUTH Wells'!E22,"") -> GURGALOT X-1 | E20: =IF(A20>0,'SOUTH Wells'!K22,"") -> 80730 | F20: =IF(A20>0,F19-E20,"") -> 4235685 | G20: =IF(A19>0,G19+E20,"") -> 468859
A21: 15 | B21: =IF(A21>0,'SOUTH Wells'!B23,"") -> 994859638 | C21: =IF(A21>0,'SOUTH Wells'!C23,"") -> 45749 | D21: =IF(A21>0,'SOUTH Wells'!E23,"") -> BETTANI DEEP-1 | E21: =IF(A21>0,'SOUTH Wells'!K23,"") -> 17475 | F21: =IF(A21>0,F20-E21,"") -> 4218210 | G21: =IF(A20>0,G20+E21,"") -> 486334
A22: 16 | B22: =IF(A22>0,'SOUTH Wells'!B24,"") -> 994859672 | C22: =IF(A22>0,'SOUTH Wells'!C24,"") -> 45754 | D22: =IF(A22>0,'SOUTH Wells'!E24,"") -> BETTANI DEEP-1 | E22: =IF(A22>0,'SOUTH Wells'!K24,"") -> 11475 | F22: =IF(A22>0,F21-E22,"") -> 4206735 | G22: =IF(A21>0,G21+E22,"") -> 497809
A23: 17 | B23: =IF(A23>0,'SOUTH Wells'!B25,"") -> 994859785 | C23: =IF(A23>0,'SOUTH Wells'!C25,"") -> 1-30 Mar-25 | D23: =IF(A23>0,'SOUTH Wells'!E25,"") -> BETTANI DEEP-1 | E23: =IF(A23>0,'SOUTH Wells'!K25,"") -> 119525 | F23: =IF(A23>0,F22-E23,"") -> 4087210 | G23: =IF(A22>0,G22+E23,"") -> 617334
A24: 18 | B24: =IF(A24>0,'SOUTH Wells'!B26,"") -> 994859647 | C24: =IF(A24>0,'SOUTH Wells'!C26,"") -> 1-28 Feb-25 | D24: =IF(A24>0,'SOUTH Wells'!E26,"") -> BARAGZAI X-1 | E24: =IF(A24>0,'SOUTH Wells'!K26,"") -> 21010 | F24: =IF(A24>0,F23-E24,"") -> 4066200 | G24: =IF(A23>0,G23+E24,"") -> 638344
A25: 19 | B25: =IF(A25>0,'SOUTH Wells'!B27,"") -> 994859843 | C25: =IF(A25>0,'SOUTH Wells'!C27,"") -> 45774 | D25: =IF(A25>0,'SOUTH Wells'!E27,"") -> BARAGZAI X-1 | E25: =IF(A25>0,'SOUTH Wells'!K27,"") -> 11640 | F25: =IF(A25>0,F24-E25,"") -> 4054560 | G25: =IF(A24>0,G24+E25,"") -> 649984
A26: 20 | B26: =IF(A26>0,'SOUTH Wells'!B28,"") -> 994859847 | C26: =IF(A26>0,'SOUTH Wells'!C28,"") -> 1-16 Mar-25 | D26: =IF(A26>0,'SOUTH Wells'!E28,"") -> RAJIAN-09 | E26: =IF(A26>0,'SOUTH Wells'!K28,"") -> 4110 | F26: =IF(A26>0,F25-E26,"") -> 4050450 | G26: =IF(A25>0,G25+E26,"") -> 654094
A27: 21 | B27: =IF(A27>0,'SOUTH Wells'!B29,"") -> 994859871 | C27: =IF(A27>0,'SOUTH Wells'!C29,"") -> 45757 | D27: =IF(A27>0,'SOUTH Wells'!E29,"") -> GURGALOT X-1 | E27: =IF(A27>0,'SOUTH Wells'!K29,"") -> 38000 | F27: =IF(A27>0,F26-E27,"") -> 4012450 | G27: =IF(A26>0,G26+E27,"") -> 692094
A28: 22 | B28: =IF(A28>0,'SOUTH Wells'!B30,"") -> 994859842 | C28: =IF(A28>0,'SOUTH Wells'!C30,"") -> 45786 | D28: =IF(A28>0,'SOUTH Wells'!E30,"") -> BARAGZAI X-1 | E28: =IF(A28>0,'SOUTH Wells'!K30,"") -> 34720 | F28: =IF(A28>0,F27-E28,"") -> 3977730 | G28: =IF(A27>0,G27+E28,"") -> 726814
... A34: 28 | B34: =IF(A34>0,'SOUTH Wells'!B36,"") -> 994859954 | C34: =IF(A34>0,'SOUTH Wells'!C36,"") -> 45824 | D34: =IF(A34>0,'SOUTH Wells'!E36,"") -> GURGALOT X-1 | E34: =IF(A34>0,'SOUTH Wells'!K36,"") -> 287550 | F34: =IF(A34>0,F33-E34,"") -> 3638342 | G34: =IF(A33>0,G33+E34,"") -> 1066202
A35: =$A34+1 -> 29 | B35: =IF(A35>0,'SOUTH Wells'!B37,"") -> 994860010 | C35: =IF(A35>0,'SOUTH Wells'!C37,"") -> 1-31 May-25 | D35: =IF(A35>0,'SOUTH Wells'!E37,"") -> KAL-03 | E35: =IF(A35>0,'SOUTH Wells'!K37,"") -> 3400 | F35: =IF(A35>0,F34-E35,"") -> 3634942 | G35: =IF(A34>0,G34+E35,"") -> 1069602
A36: =$A35+1 -> 30 | B36: =IF(A36>0,'SOUTH Wells'!B38,"") -> 994860011 | C36: =IF(A36>0,'SOUTH Wells'!C38,"") -> 1-30 April-25 | D36: =IF(A36>0,'SOUTH Wells'!E38,"") -> GURGALOT X-1 | E36: =IF(A36>0,'SOUTH Wells'!K38,"") -> 26220 | F36: =IF(A36>0,F35-E36,"") -> 3608722 | G36: =IF(A35>0,G35+E36,"") -> 1095822
A37: =$A36+1 -> 31 | B37: =IF(A37>0,'SOUTH Wells'!B39,"") -> 994860039 | C37: =IF(A37>0,'SOUTH Wells'!C39,"") -> 1-31 May-25 | D37: =IF(A37>0,'SOUTH Wells'!E39,"") -> RAJIAN-02 | E37: =IF(A37>0,'SOUTH Wells'!K39,"") -> 5940 | F37: =IF(A37>0,F36-E37,"") -> 3602782 | G37: =IF(A36>0,G36+E37,"") -> 1101762
A38: =$A37+1 -> 32 | B38: =IF(A38>0,'SOUTH Wells'!B40,"") -> 994860040 | C38: =IF(A38>0,'SOUTH Wells'!C40,"") -> 23-30 June-25 | D38: =IF(A38>0,'SOUTH Wells'!E40,"") -> RAJIAN-02 | E38: =IF(A38>0,'SOUTH Wells'!K40,"") -> 10150 | F38: =IF(A38>0,F37-E38,"") -> 3592632 | G38: =IF(A37>0,G37+E38,"") -> 1111912
A39: =$A38+1 -> 33 | B39: =IF(A39>0,'SOUTH Wells'!B41,"") -> 994860195 | C39: =IF(A39>0,'SOUTH Wells'!C41,"") -> 29-30 June-25 | D39: =IF(A39>0,'SOUTH Wells'!E41,"") -> BARAGZAI X-1 | E39: =IF(A39>0,'SOUTH Wells'!K41,"") -> 80252.5 | F39: =IF(A39>0,F38-E39,"") -> 3512379.5 | G39: =IF(A38>0,G38+E39,"") -> 1192164.5
A40: =$A39+1 -> 34 | B40: =IF(A40>0,'SOUTH Wells'!B42,"") -> 994860151 | C40: =IF(A40>0,'SOUTH Wells'!C42,"") -> 45850 | D40: =IF(A40>0,'SOUTH Wells'!E42,"") -> RAJIAN-08 | E40: =IF(A40>0,'SOUTH Wells'!K42,"") -> 4098 | F40: =IF(A40>0,F39-E40,"") -> 3508281.5 | G40: =IF(A39>0,G39+E40,"") -> 1196262.5
A41: =$A40+1 -> 35 | B41: =IF(A41>0,'SOUTH Wells'!B43,"") -> 994860152 | C41: =IF(A41>0,'SOUTH Wells'!C43,"") -> 45840 | D41: =IF(A41>0,'SOUTH Wells'!E43,"") -> GURGALOT X-1 | E41: =IF(A41>0,'SOUTH Wells'!K43,"") -> 107060 | F41: =IF(A41>0,F40-E41,"") -> 3401221.5 | G41: =IF(A40>0,G40+E41,"") -> 1303322.5
A42: =$A41+1 -> 36 | B42: =IF(A42>0,'SOUTH Wells'!B44,"") -> 994860199 | C42: =IF(A42>0,'SOUTH Wells'!C44,"") -> 45840 | D42: =IF(A42>0,'SOUTH Wells'!E44,"") -> CHAK 203-1 | E42: =IF(A42>0,'SOUTH Wells'!K44,"") -> 30340 | F42: =IF(A42>0,F41-E42,"") -> 3370881.5 | G42: =IF(A41>0,G41+E42,"") -> 1333662.5
A43: =$A42+1 -> 37 | B43: =IF(A43>0,'SOUTH Wells'!B45,"") -> 994860226 | C43: =IF(A43>0,'SOUTH Wells'!C45,"") -> 25-30 June-25 | D43: =IF(A43>0,'SOUTH Wells'!E45,"") -> CHAK 203-1 | E43: =IF(A43>0,'SOUTH Wells'!K45,"") -> 39250 | F43: =IF(A43>0,F42-E43,"") -> 3331631.5 | G43: =IF(A42>0,G42+E43,"") -> 1372912.5
A44: =$A43+1 -> 38 | B44: =IF(A44>0,'SOUTH Wells'!B46,"") -> 994860264 | C44: =IF(A44>0,'SOUTH Wells'!C46,"") -> 08-17 June-25 | D44: =IF(A44>0,'SOUTH Wells'!E46,"") -> CHAK 203-1 | E44: =IF(A44>0,'SOUTH Wells'!K46,"") -> 4825 | F44: =IF(A44>0,F43-E44,"") -> 3326806.5 | G44: =IF(A43>0,G43+E44,"") -> 1377737.5
A45: =$A44+1 -> 39 | B45: =IF(A45>0,'SOUTH Wells'!B47,"") -> 994860265 | C45: =IF(A45>0,'SOUTH Wells'!C47,"") -> 02-13 Apr-25 | D45: =IF(A45>0,'SOUTH Wells'!E47,"") -> CHAK 203-1 | E45: =IF(A45>0,'SOUTH Wells'!K47,"") -> 2772 | F45: =IF(A45>0,F44-E45,"") -> 3324034.5 | G45: =IF(A44>0,G44+E45,"") -> 1380509.5
...
